Traceback (most recent call last):
  File "/Library/Frameworks/Python.framework/Versions/3.9/bin/beneath", line 8, in <module>
    sys.exit(main())
  File "/Library/Frameworks/Python.framework/Versions/3.9/lib/python3.9/site-packages/beneath/cli/__init__.py", line 25, in main
    func(args)
  File "/Library/Frameworks/Python.framework/Versions/3.9/lib/python3.9/site-packages/beneath/cli/utils.py", line 16, in wrapped
    loop.run_until_complete(cmd(args))
  File "/Library/Frameworks/Python.framework/Versions/3.9/lib/python3.9/asyncio/base_events.py", line 642, in run_until_complete
    return future.result()
  File "/Library/Frameworks/Python.framework/Versions/3.9/lib/python3.9/site-packages/beneath/cli/project.py", line 109, in create
    organization = await client.admin.organizations.find_by_name(pq.organization)
  File "/Library/Frameworks/Python.framework/Versions/3.9/lib/python3.9/site-packages/beneath/admin/organizations.py", line 49, in find_by_name
    result = await self.conn.query_control(
  File "/Library/Frameworks/Python.framework/Versions/3.9/lib/python3.9/site-packages/beneath/connection.py", line 126, in query_control
    async with session.post(url=url, headers=headers, json=body) as response:
  File "/Library/Frameworks/Python.framework/Versions/3.9/lib/python3.9/site-packages/aiohttp/client.py", line 1117, in __aenter__
    self._resp = await self._coro
  File "/Library/Frameworks/Python.framework/Versions/3.9/lib/python3.9/site-packages/aiohttp/client.py", line 520, in _request
    conn = await self._connector.connect(
  File "/Library/Frameworks/Python.framework/Versions/3.9/lib/python3.9/site-packages/aiohttp/connector.py", line 535, in connect
    proto = await self._create_connection(req, traces, timeout)
  File "/Library/Frameworks/Python.framework/Versions/3.9/lib/python3.9/site-packages/aiohttp/connector.py", line 892, in _create_connection
    _, proto = await self._create_direct_connection(req, traces, timeout)
  File "/Library/Frameworks/Python.framework/Versions/3.9/lib/python3.9/site-packages/aiohttp/connector.py", line 1051, in _create_direct_connection
    raise last_exc
  File "/Library/Frameworks/Python.framework/Versions/3.9/lib/python3.9/site-packages/aiohttp/connector.py", line 1020, in _create_direct_connection
    transp, proto = await self._wrap_create_connection(
  File "/Library/Frameworks/Python.framework/Versions/3.9/lib/python3.9/site-packages/aiohttp/connector.py", line 971, in _wrap_create_connection
    raise ClientConnectorCertificateError(req.connection_key, exc) from exc
aiohttp.client_exceptions.ClientConnectorCertificateError: Cannot connect to host control.beneath.dev:443 ssl:True [SSLCertVerificationError: (1, '[SSL: CERTIFICATE_VERIFY_FAILED] certificate verify failed: unable to get local issuer certificate (_ssl.c:1122)')]